Workbook

Sheet Customer_Master
A1: Customer Master List (clean reference table)
A2: Authoritative source used to reconcile messy order entries
A4: CustomerID | B4: CustomerName | C4: Segment | D4: Region
A5: CUST0001 | B5: Ola Lawal | C5: Champions | D5: Ibadan
A6: CUST0002 | B6: Tunde Ajayi | C6: Loyal | D6: Abuja
A7: CUST0003 | B7: Chidi Adamu | C7: Champions | D7: Enugu
A8: CUST0004 | B8: Grace Duru | C8: Champions | D8: Kano
A9: CUST0005 | B9: Tunde Nnamdi | C9: New | D9: Lagos
A10: CUST0006 | B10: Joy Nwosu | C10: New | D10: Enugu
A11: CUST0007 | B11: Tunde Okonkwo | C11: New | D11: Ibadan
A12: CUST0008 | B12: Victor Duru | C12: Loyal | D12: Enugu
A13: CUST0009 | B13: Ngozi Sani | C13: Loyal | D13: Kano
A14: CUST0010 | B14: Esther Umeh | C14: Champions | D14: Abuja
A15: CUST0011 | B15: Musa Lawal | C15: At Risk | D15: Jos
... A64: CUST0060 | B64: James Umeh | C64: Champions | D64: Kano

Sheet Orders_Raw
A1: Raw Order Entries (as received — unedited)
A2: 535 order records with realistic entry errors: inconsistent casing/spacing, mixed date and currency formats, typo'd customer IDs, missing/invalid quantities, duplicate re-entries
A4: OrderID | B4: CustomerID | C4: CustomerName | D4: OrderDate | E4: Product | F4: Quantity | G4: Amount | H4: EntryTimestamp
A5: ORD00385 | B5: CUST0049 | C5: BISI AJAYI | D5: 04-May-2026 | E5: Tablet | F5: 3 | G5: NGN 1,557.36 | H5: 2026-05-04 12:25
A6: ORD00402 | B6: CUST0001 | C6: ola lawal | D6: 30-Mar-2026 | E6: Printer | F6: 4 | G6: $1,180.96 | H6: 2026-03-30 12:00
A7: ORD00281 | B7: CUST0041 | C7: Kemi Umeh | D7: 08-Mar-2026 | E7: Keyboard | F7: 1 | G7: $2,278.35 | H7: 2026-03-08 12:33
A8: ORD00145 | B8: CUST0003 | C8: Chidi Adamu | D8: 2026-05-24 | E8: Tablet | F8: 1 | G8: 915.87 | H8: 2026-05-24 12:52
A9: ORD00279 | B9: CUST0060 | C9: james umeh | D9: 02-May-2026 | E9: Speaker | F9: 3 | G9: $211.20 | H9: 2026-05-02 18:39
A10: ORD00376 | B10: CUST0013 | C10: Joy Lawal | D10: 2026-03-15 | E10: Headphones | F10: 3 | G10: $ 98.52 | H10: 2026-03-15 18:02
A11: ORD00207 | B11: CUST0016 | C11: Chidi Ajayi | D11: 2026-02-12 | E11: Phone | F11: 5 | G11: NGN 125.08 | H11: 2026-02-12 08:06
A12: ORD00196 | B12: CUST0006 | C12: Joy Nwosu | D12: 05/03/2026 | E12: Monitor | F12: 2 | G12: 218.86 | H12: 2026-03-05 13:23
A13: ORD00153 | B13: CUST0021 | C13: Joy Ajayi | D13: 17-May-2026 | E13: Mouse | F13: 3 | G13: 1,372.49 | H13: 2026-05-17 16:19
A14: ORD00132 | B14: CUST0020 | C14: mary okafor | D14: 2026-04-03 | E14: Laptop | F14: 5 | G14: 572.24 | H14: 2026-04-03 13:35
A15: ORD00024 | B15: CUST0013 | C15: Joy Lawal | D15: 07/05/2026 | E15: Monitor | F15: 5 | G15: $621.30 | H15: 2026-05-07 11:11
... A139: ORD00483 | B139: CUST0026 | C139: amaka yakubu | D139: 2026-06-08 | E139: Speaker | F139: 2 | G139: NGN 1,376.65 | H139: 2026-06-08 14:50
A140: ORD00435 | B140: CUST0043 | C140: Grace Ajayi | D140: 2026-03-31 | E140: Mouse | G140: $ 812.03 | H140: 2026-03-31 10:22
A141: ORD00415 | B141: CUST0029 | C141: James Uche | D141: 28/06/2026 | E141: Mouse | F141: 3 | G141: 486.59 | H141: 2026-06-28 17:58
A142: ORD00434 | B142: CUST0037 | C142: Blessing Obi | D142: 2026-07-08 | E142: Speaker | F142: 2 | G142: $626.92 | H142: 2026-07-08 09:07
A143: ORD00393 | B143: CUST0008 | C143: Victor Duru | D143: 2026-02-20 | E143: Keyboard | F143: 1 | G143: $ 1,446.10 | H143: 2026-02-20 18:32
A144: ORD00460 | B144: CUST0006 | C144: JOY NWOSU | D144: 2026-03-04 | E144: Headphones | F144: 5 | G144: $ 706.11 | H144: 2026-03-04 08:41
A145: ORD00032 | B145: CUST0002 | C145: tunde ajayi | D145: 2026-04-29 | E145: Monitor | F145: 2 | G145: NGN 139.96 | H145: 2026-04-29 12:48
A146: ORD00388 | B146: CUST0036 | C146: Esther Umeh | D146: 2026-05-01 | E146: Keyboard | F146: 2 | G146: 867.59 | H146: 2026-05-01 13:54
A147: ORD00270 | B147: CUST0017 | C147: IBRAHIM AJAYI | D147: 31-Mar-2026 | E147: Headphones | F147: 1 | G147: $1,970.74 | H147: 2026-03-31 14:31
A148: ORD00164 | B148: CUST0047 | C148: Amaka Adamu | D148: 17-Jun-2026 | E148: Monitor | F148: 4 | G148: $1,736.53 | H148: 2026-06-17 18:32
A149: ORD00341 | B149: CUST0003 | C149: chidi adamu | D149: 2026-03-24 | E149: Tablet | F149: 1 | G149: $219.63 | H149: 2026-03-24 08:40
A150: ORD00115 | B150: CUST0058 | C150: Blessing Balogun | D150: 2026-01-24 | E150: Keyboard | F150: 1 | G150: 2,044.51 | H150: 2026-01-24 11:24
A151: ORD00124 | B151: CUST0056 | C151: Tunde Yakubu | D151: 11/03/2026 | E151: Monitor | F151: 2 | G151: NGN 2,001.37 | H151: 2026-03-11 13:11
A152: ORD00379 | B152: CUST0013 | C152: Joy Lawal | D152: 28/05/2026 | E152: Mouse | F152: 3 | G152: NGN 663.85 | H152: 2026-05-28 13:07
... A164: ORD00464 | B164: CUST0027 | C164: yusuf sani | D164: 06/06/2026 | E164: Mouse | F164: 1 | G164: $ 286.62 | H164: 2026-06-06 14:38
A165: ORD00011 | B165: CUST0022 | C165: Musa Sani | D165: 11/02/2026 | E165: Phone | G165: NGN 1,385.93 | H165: 2026-02-11 10:34
A166: ORD00030 | B166: CUST0020 | C166: Mary Okafor | D166: 2026-05-18 | E166: Laptop | F166: 2 | G166: 2002.67 | H166: 2026-05-18 14:21
A167: ORD00491 | B167: CUST0025 | C167: Fatima Okafor | D167: 2026-04-17 | E167: Laptop | G167: 731.85 | H167: 2026-04-17 10:46
A168: ORD00170 | B168: CUST0054 | C168: Comfort Adeyemi | D168: 19/01/2026 | E168: Phone | F168: 3 | G168: $1,067.89 | H168: 2026-01-19 15:02
A169: ORD00040 | B169: CUST0043 | C169: GRACE AJAYI | D169: 07-May-2026 | E169: Speaker | F169: 2 | G169: 466.87 | H169: 2026-05-07 12:35
A170: ORD00506 | B170: CUST0001 | C170: OLA LAWAL | D170: 04/01/2026 | E170: Mouse | F170: 4 | G170: $257.78 | H170: 2026-01-04 12:12
A171: ORD00396 | B171: CUST0018 | C171: Fatima Okonkwo | D171: 2026-07-11 | E171: Headphones | F171: 2 | G171: NGN 1,309.53 | H171: 2026-07-11 11:42
A172: ORD00450 | B172: CUSTO015 | C172: Ahmed Nwosu | D172: 2026-04-16 | E172: Printer | F172: 5 | G172: 1859.78 | H172: 2026-04-16 17:31
A173: ORD00138 | B173: CUST0060 | C173: JAMES UMEH | D173: 21/01/2026 | E173: Monitor | F173: 2 | G173: $ 2,372.14 | H173: 2026-01-21 17:40
A174: ORD00371 | B174: CUST0024 | C174: Aisha Adeyemi | D174: 06-Mar-2026 | E174: Monitor | F174: 3 | G174: NGN 2,139.62 | H174: 2026-03-06 11:26
A175: ORD00466 | B175: CUST0012 | C175: kemi sani | D175: 01-Jul-2026 | E175: Phone | G175: $2,448.46 | H175: 2026-07-01 11:51
...

Sheet Cleaned_Orders
A1: Cleaned, Validated & Reconciled Orders
A2: Every value below is a live formula pulling from Orders_Raw and Customer_Master
A4: OrderID | B4: Clean CustomerID | C4: Clean Name | D4: Parsed Date | E4: Date Valid? | F4: Clean Amount | G4: Amount Valid? | H4: Quantity | I4: Qty Valid? | J4: Product | K4: Entry Timestamp | L4: Duplicate OrderID? | M4: Near-Duplicate? | N4: Master Name | O4: Segment | P4: Region | Q4: Match Status | R4: Overall Status
A5: =Orders_Raw!A5 -> ORD00385 | B5: =TRIM(UPPER(Orders_Raw!B5)) -> CUST0049 | C5: =PROPER(TRIM(Orders_Raw!C5)) -> Bisi Ajayi | D5: =IFERROR(DATEVALUE(Orders_Raw!D5),"") -> 46146 | E5: =IF(D5="","No","Yes") -> Yes | F5: =IFERROR(VALUE(SUBSTITUTE(SUBSTITUTE(SUBSTITUTE(Orders_Raw!G5,"$",""),"NGN",""),",","")),"") -> 1557.36 | G5: =IF(F5="","No","Yes") -> Yes | H5: =Orders_Raw!F5 -> 3 | I5: =IF(H5="","No",IF(H5<=0,"No","Yes")) -> Yes | J5: =Orders_Raw!E5 -> Tablet | K5: =Orders_Raw!H5 -> 2026-05-04 12:25 | L5: =IF(COUNTIF(Orders_Raw!$A$5:$A$539,A5)>1,"YES","No") -> No | M5: =IF(COUNTIFS($B$5:$B$539,B5,$D$5:$D$539,D5,$F$5:$F$539,F5)>1,"YES","No") -> No | N5: =IFERROR(INDEX(Customer_Master!$B$5:$B$64,MATCH(B5,Customer_Master!$A$5:$A$64,0)),"UNMATCHED") -> Bisi Ajayi | O5: =IFERROR(INDEX(Customer_Master!$C$5:$C$64,MATCH(B5,Customer_Master!$A$5:$A$64,0)),"UNMATCHED") -> Loyal | P5: =IFERROR(INDEX(Customer_Master!$D$5:$D$64,MATCH(B5,Customer_Master!$A$5:$A$64,0)),"UNMATCHED") -> Abuja | Q5: =IF(N5="UNMATCHED","Unmatched","Matched") -> Matched | R5: =IF(OR(E5="No",G5="No",I5="No",L5="YES",Q5="Unmatched"),"NEEDS REVIEW","OK") -> OK
A6: =Orders_Raw!A6 -> ORD00402 | B6: =TRIM(UPPER(Orders_Raw!B6)) -> CUST0001 | C6: =PROPER(TRIM(Orders_Raw!C6)) -> Ola Lawal | D6: =IFERROR(DATEVALUE(Orders_Raw!D6),"") -> 46111 | E6: =IF(D6="","No","Yes") -> Yes | F6: =IFERROR(VALUE(SUBSTITUTE(SUBSTITUTE(SUBSTITUTE(Orders_Raw!G6,"$",""),"NGN",""),",","")),"") -> 1180.96 | G6: =IF(F6="","No","Yes") -> Yes | H6: =Orders_Raw!F6 -> 4 | I6: =IF(H6="","No",IF(H6<=0,"No","Yes")) -> Yes | J6: =Orders_Raw!E6 -> Printer | K6: =Orders_Raw!H6 -> 2026-03-30 12:00 | L6: =IF(COUNTIF(Orders_Raw!$A$5:$A$539,A6)>1,"YES","No") -> No | M6: =IF(COUNTIFS($B$5:$B$539,B6,$D$5:$D$539,D6,$F$5:$F$539,F6)>1,"YES","No") -> No | N6: =IFERROR(INDEX(Customer_Master!$B$5:$B$64,MATCH(B6,Customer_Master!$A$5:$A$64,0)),"UNMATCHED") -> Ola Lawal | O6: =IFERROR(INDEX(Customer_Master!$C$5:$C$64,MATCH(B6,Customer_Master!$A$5:$A$64,0)),"UNMATCHED") -> Champions | P6: =IFERROR(INDEX(Customer_Master!$D$5:$D$64,MATCH(B6,Customer_Master!$A$5:$A$64,0)),"UNMATCHED") -> Ibadan | Q6: =IF(N6="UNMATCHED","Unmatched","Matched") -> Matched | R6: =IF(OR(E6="No",G6="No",I6="No",L6="YES",Q6="Unmatched"),"NEEDS REVIEW","OK") -> OK
A7: =Orders_Raw!A7 -> ORD00281 | B7: =TRIM(UPPER(Orders_Raw!B7)) -> CUST0041 | C7: =PROPER(TRIM(Orders_Raw!C7)) -> Kemi Umeh | D7: =IFERROR(DATEVALUE(Orders_Raw!D7),"") -> 46089 | E7: =IF(D7="","No","Yes") -> Yes | F7: =IFERROR(VALUE(SUBSTITUTE(SUBSTITUTE(SUBSTITUTE(Orders_Raw!G7,"$",""),"NGN",""),",","")),"") -> 2278.35 | G7: =IF(F7="","No","Yes") -> Yes | H7: =Orders_Raw!F7 -> 1 | I7: =IF(H7="","No",IF(H7<=0,"No","Yes")) -> Yes | J7: =Orders_Raw!E7 -> Keyboard | K7: =Orders_Raw!H7 -> 2026-03-08 12:33 | L7: =IF(COUNTIF(Orders_Raw!$A$5:$A$539,A7)>1,"YES","No") -> YES | M7: =IF(COUNTIFS($B$5:$B$539,B7,$D$5:$D$539,D7,$F$5:$F$539,F7)>1,"YES","No") -> YES | N7: =IFERROR(INDEX(Customer_Master!$B$5:$B$64,MATCH(B7,Customer_Master!$A$5:$A$64,0)),"UNMATCHED") -> Kemi Umeh | O7: =IFERROR(INDEX(Customer_Master!$C$5:$C$64,MATCH(B7,Customer_Master!$A$5:$A$64,0)),"UNMATCHED") -> Lost / Low-Value | P7: =IFERROR(INDEX(Customer_Master!$D$5:$D$64,MATCH(B7,Customer_Master!$A$5:$A$64,0)),"UNMATCHED") -> Lagos | Q7: =IF(N7="UNMATCHED","Unmatched","Matched") -> Matched | R7: =IF(OR(E7="No",G7="No",I7="No",L7="YES",Q7="Unmatched"),"NEEDS REVIEW","OK") -> NEEDS REVIEW
A8: =Orders_Raw!A8 -> ORD00145 | B8: =TRIM(UPPER(Orders_Raw!B8)) -> CUST0003 | C8: =PROPER(TRIM(Orders_Raw!C8)) -> Chidi Adamu | D8: =IFERROR(DATEVALUE(Orders_Raw!D8),"") -> 46166 | E8: =IF(D8="","No","Yes") -> Yes | F8: =IFERROR(VALUE(SUBSTITUTE(SUBSTITUTE(SUBSTITUTE(Orders_Raw!G8,"$",""),"NGN",""),",","")),"") -> 915.87 | G8: =IF(F8="","No","Yes") -> Yes | H8: =Orders_Raw!F8 -> 1 | I8: =IF(H8="","No",IF(H8<=0,"No","Yes")) -> Yes | J8: =Orders_Raw!E8 -> Tablet | K8: =Orders_Raw!H8 -> 2026-05-24 12:52 | L8: =IF(COUNTIF(Orders_Raw!$A$5:$A$539,A8)>1,"YES","No") -> YES | M8: =IF(COUNTIFS($B$5:$B$539,B8,$D$5:$D$539,D8,$F$5:$F$539,F8)>1,"YES","No") -> YES | N8: =IFERROR(INDEX(Customer_Master!$B$5:$B$64,MATCH(B8,Customer_Master!$A$5:$A$64,0)),"UNMATCHED") -> Chidi Adamu | O8: =IFERROR(INDEX(Customer_Master!$C$5:$C$64,MATCH(B8,Customer_Master!$A$5:$A$64,0)),"UNMATCHED") -> Champions | P8: =IFERROR(INDEX(Customer_Master!$D$5:$D$64,MATCH(B8,Customer_Master!$A$5:$A$64,0)),"UNMATCHED") -> Enugu | Q8: =IF(N8="UNMATCHED","Unmatched","Matched") -> Matched | R8: =IF(OR(E8="No",G8="No",I8="No",L8="YES",Q8="Unmatched"),"NEEDS REVIEW","OK") -> NEEDS REVIEW
A9: =Orders_Raw!A9 -> ORD00279 | B9: =TRIM(UPPER(Orders_Raw!B9)) -> CUST0060 | C9: =PROPER(TRIM(Orders_Raw!C9)) -> James Umeh | D9: =IFERROR(DATEVALUE(Orders_Raw!D9),"") -> 46144 | E9: =IF(D9="","No","Yes") -> Yes | F9: =IFERROR(VALUE(SUBSTITUTE(SUBSTITUTE(SUBSTITUTE(Orders_Raw!G9,"$",""),"NGN",""),",","")),"") -> 211.2 | G9: =IF(F9="","No","Yes") -> Yes | H9: =Orders_Raw!F9 -> 3 | I9: =IF(H9="","No",IF(H9<=0,"No","Yes")) -> Yes | J9: =Orders_Raw!E9 -> Speaker | K9: =Orders_Raw!H9 -> 2026-05-02 18:39 | L9: =IF(COUNTIF(Orders_Raw!$A$5:$A$539,A9)>1,"YES","No") -> No | M9: =IF(COUNTIFS($B$5:$B$539,B9,$D$5:$D$539,D9,$F$5:$F$539,F9)>1,"YES","No") -> No | N9: =IFERROR(INDEX(Customer_Master!$B$5:$B$64,MATCH(B9,Customer_Master!$A$5:$A$64,0)),"UNMATCHED") -> James Umeh | O9: =IFERROR(INDEX(Customer_Master!$C$5:$C$64,MATCH(B9,Customer_Master!$A$5:$A$64,0)),"UNMATCHED") -> Champions | P9: =IFERROR(INDEX(Customer_Master!$D$5:$D$64,MATCH(B9,Customer_Master!$A$5:$A$64,0)),"UNMATCHED") -> Kano | Q9: =IF(N9="UNMATCHED","Unmatched","Matched") -> Matched | R9: =IF(OR(E9="No",G9="No",I9="No",L9="YES",Q9="Unmatched"),"NEEDS REVIEW","OK") -> OK
A10: =Orders_Raw!A10 -> ORD00376 | B10: =TRIM(UPPER(Orders_Raw!B10)) -> CUST0013 | C10: =PROPER(TRIM(Orders_Raw!C10)) -> Joy Lawal | D10: =IFERROR(DATEVALUE(Orders_Raw!D10),"") -> 46096 | E10: =IF(D10="","No","Yes") -> Yes | F10: =IFERROR(VALUE(SUBSTITUTE(SUBSTITUTE(SUBSTITUTE(Orders_Raw!G10,"$",""),"NGN",""),",","")),"") -> 98.52 | G10: =IF(F10="","No","Yes") -> Yes | H10: =Orders_Raw!F10 -> 3 | I10: =IF(H10="","No",IF(H10<=0,"No","Yes")) -> Yes | J10: =Orders_Raw!E10 -> Headphones | K10: =Orders_Raw!H10 -> 2026-03-15 18:02 | L10: =IF(COUNTIF(Orders_Raw!$A$5:$A$539,A10)>1,"YES","No") -> No | M10: =IF(COUNTIFS($B$5:$B$539,B10,$D$5:$D$539,D10,$F$5:$F$539,F10)>1,"YES","No") -> No | N10: =IFERROR(INDEX(Customer_Master!$B$5:$B$64,MATCH(B10,Customer_Master!$A$5:$A$64,0)),"UNMATCHED") -> Joy Lawal | O10: =IFERROR(INDEX(Customer_Master!$C$5:$C$64,MATCH(B10,Customer_Master!$A$5:$A$64,0)),"UNMATCHED") -> Lost / Low-Value | P10: =IFERROR(INDEX(Customer_Master!$D$5:$D$64,MATCH(B10,Customer_Master!$A$5:$A$64,0)),"UNMATCHED") -> Abuja | Q10: =IF(N10="UNMATCHED","Unmatched","Matched") -> Matched | R10: =IF(OR(E10="No",G10="No",I10="No",L10="YES",Q10="Unmatched"),"NEEDS REVIEW","OK") -> OK
A11: =Orders_Raw!A11 -> ORD00207 | B11: =TRIM(UPPER(Orders_Raw!B11)) -> CUST0016 | C11: =PROPER(TRIM(Orders_Raw!C11)) -> Chidi Ajayi | D11: =IFERROR(DATEVALUE(Orders_Raw!D11),"") -> 46065 | E11: =IF(D11="","No","Yes") -> Yes | F11: =IFERROR(VALUE(SUBSTITUTE(SUBSTITUTE(SUBSTITUTE(Orders_Raw!G11,"$",""),"NGN",""),",","")),"") -> 125.08 | G11: =IF(F11="","No","Yes") -> Yes | H11: =Orders_Raw!F11 -> 5 | I11: =IF(H11="","No",IF(H11<=0,"No","Yes")) -> Yes | J11: =Orders_Raw!E11 -> Phone | K11: =Orders_Raw!H11 -> 2026-02-12 08:06 | L11: =IF(COUNTIF(Orders_Raw!$A$5:$A$539,A11)>1,"YES","No") -> No | M11: =IF(COUNTIFS($B$5:$B$539,B11,$D$5:$D$539,D11,$F$5:$F$539,F11)>1,"YES","No") -> No | N11: =IFERROR(INDEX(Customer_Master!$B$5:$B$64,MATCH(B11,Customer_Master!$A$5:$A$64,0)),"UNMATCHED") -> Chidi Ajayi | O11: =IFERROR(INDEX(Customer_Master!$C$5:$C$64,MATCH(B11,Customer_Master!$A$5:$A$64,0)),"UNMATCHED") -> At Risk | P11: =IFERROR(INDEX(Customer_Master!$D$5:$D$64,MATCH(B11,Customer_Master!$A$5:$A$64,0)),"UNMATCHED") -> Abuja | Q11: =IF(N11="UNMATCHED","Unmatched","Matched") -> Matched | R11: =IF(OR(E11="No",G11="No",I11="No",L11="YES",Q11="Unmatched"),"NEEDS REVIEW","OK") -> OK
A12: =Orders_Raw!A12 -> ORD00196 | B12: =TRIM(UPPER(Orders_Raw!B12)) -> CUST0006 | C12: =PROPER(TRIM(Orders_Raw!C12)) -> Joy Nwosu | D12: =IFERROR(DATEVALUE(Orders_Raw!D12),"") -> 46145 | E12: =IF(D12="","No","Yes") -> Yes | F12: =IFERROR(VALUE(SUBSTITUTE(SUBSTITUTE(SUBSTITUTE(Orders_Raw!G12,"$",""),"NGN",""),",","")),"") -> 218.86 | G12: =IF(F12="","No","Yes") -> Yes | H12: =Orders_Raw!F12 -> 2 | I12: =IF(H12="","No",IF(H12<=0,"No","Yes")) -> Yes | J12: =Orders_Raw!E12 -> Monitor | K12: =Orders_Raw!H12 -> 2026-03-05 13:23 | L12: =IF(COUNTIF(Orders_Raw!$A$5:$A$539,A12)>1,"YES","No") -> No | M12: =IF(COUNTIFS($B$5:$B$539,B12,$D$5:$D$539,D12,$F$5:$F$539,F12)>1,"YES","No") -> No | N12: =IFERROR(INDEX(Customer_Master!$B$5:$B$64,MATCH(B12,Customer_Master!$A$5:$A$64,0)),"UNMATCHED") -> Joy Nwosu | O12: =IFERROR(INDEX(Customer_Master!$C$5:$C$64,MATCH(B12,Customer_Master!$A$5:$A$64,0)),"UNMATCHED") -> New | P12: =IFERROR(INDEX(Customer_Master!$D$5:$D$64,MATCH(B12,Customer_Master!$A$5:$A$64,0)),"UNMATCHED") -> Enugu | Q12: =IF(N12="UNMATCHED","Unmatched","Matched") -> Matched | R12: =IF(OR(E12="No",G12="No",I12="No",L12="YES",Q12="Unmatched"),"NEEDS REVIEW","OK") -> OK
A13: =Orders_Raw!A13 -> ORD00153 | B13: =TRIM(UPPER(Orders_Raw!B13)) -> CUST0021 | C13: =PROPER(TRIM(Orders_Raw!C13)) -> Joy Ajayi | D13: =IFERROR(DATEVALUE(Orders_Raw!D13),"") -> 46159 | E13: =IF(D13="","No","Yes") -> Yes | F13: =IFERROR(VALUE(SUBSTITUTE(SUBSTITUTE(SUBSTITUTE(Orders_Raw!G13,"$",""),"NGN",""),",","")),"") -> 1372.49 | G13: =IF(F13="","No","Yes") -> Yes | H13: =Orders_Raw!F13 -> 3 | I13: =IF(H13="","No",IF(H13<=0,"No","Yes")) -> Yes | J13: =Orders_Raw!E13 -> Mouse | K13: =Orders_Raw!H13 -> 2026-05-17 16:19 | L13: =IF(COUNTIF(Orders_Raw!$A$5:$A$539,A13)>1,"YES","No") -> No | M13: =IF(COUNTIFS($B$5:$B$539,B13,$D$5:$D$539,D13,$F$5:$F$539,F13)>1,"YES","No") -> No | N13: =IFERROR(INDEX(Customer_Master!$B$5:$B$64,MATCH(B13,Customer_Master!$A$5:$A$64,0)),"UNMATCHED") -> Joy Ajayi | O13: =IFERROR(INDEX(Customer_Master!$C$5:$C$64,MATCH(B13,Customer_Master!$A$5:$A$64,0)),"UNMATCHED") -> Loyal | P13: =IFERROR(INDEX(Customer_Master!$D$5:$D$64,MATCH(B13,Customer_Master!$A$5:$A$64,0)),"UNMATCHED") -> Kaduna | Q13: =IF(N13="UNMATCHED","Unmatched","Matched") -> Matched | R13: =IF(OR(E13="No",G13="No",I13="No",L13="YES",Q13="Unmatched"),"NEEDS REVIEW","OK") -> OK
A14: =Orders_Raw!A14 -> ORD00132 | B14: =TRIM(UPPER(Orders_Raw!B14)) -> CUST0020 | C14: =PROPER(TRIM(Orders_Raw!C14)) -> Mary Okafor | D14: =IFERROR(DATEVALUE(Orders_Raw!D14),"") -> 46115 | E14: =IF(D14="","No","Yes") -> Yes | F14: =IFERROR(VALUE(SUBSTITUTE(SUBSTITUTE(SUBSTITUTE(Orders_Raw!G14,"$",""),"NGN",""),",","")),"") -> 572.24 | G14: =IF(F14="","No","Yes") -> Yes | H14: =Orders_Raw!F14 -> 5 | I14: =IF(H14="","No",IF(H14<=0,"No","Yes")) -> Yes | J14: =Orders_Raw!E14 -> Laptop | K14: =Orders_Raw!H14 -> 2026-04-03 13:35 | L14: =IF(COUNTIF(Orders_Raw!$A$5:$A$539,A14)>1,"YES","No") -> No | M14: =IF(COUNTIFS($B$5:$B$539,B14,$D$5:$D$539,D14,$F$5:$F$539,F14)>1,"YES","No") -> No | N14: =IFERROR(INDEX(Customer_Master!$B$5:$B$64,MATCH(B14,Customer_Master!$A$5:$A$64,0)),"UNMATCHED") -> Mary Okafor | O14: =IFERROR(INDEX(Customer_Master!$C$5:$C$64,MATCH(B14,Customer_Master!$A$5:$A$64,0)),"UNMATCHED") -> New | P14: =IFERROR(INDEX(Customer_Master!$D$5:$D$64,MATCH(B14,Customer_Master!$A$5:$A$64,0)),"UNMATCHED") -> Port Harcourt | Q14: =IF(N14="UNMATCHED","Unmatched","Matched") -> Matched | R14: =IF(OR(E14="No",G14="No",I14="No",L14="YES",Q14="Unmatched"),"NEEDS REVIEW","OK") -> OK
A15: =Orders_Raw!A15 -> ORD00024 | B15: =TRIM(UPPER(Orders_Raw!B15)) -> CUST0013 | C15: =PROPER(TRIM(Orders_Raw!C15)) -> Joy Lawal | D15: =IFERROR(DATEVALUE(Orders_Raw!D15),"") -> 46208 | E15: =IF(D15="","No","Yes") -> Yes | F15: =IFERROR(VALUE(SUBSTITUTE(SUBSTITUTE(SUBSTITUTE(Orders_Raw!G15,"$",""),"NGN",""),",","")),"") -> 621.3 | G15: =IF(F15="","No","Yes") -> Yes | H15: =Orders_Raw!F15 -> 5 | I15: =IF(H15="","No",IF(H15<=0,"No","Yes")) -> Yes | J15: =Orders_Raw!E15 -> Monitor | K15: =Orders_Raw!H15 -> 2026-05-07 11:11 | L15: =IF(COUNTIF(Orders_Raw!$A$5:$A$539,A15)>1,"YES","No") -> No | M15: =IF(COUNTIFS($B$5:$B$539,B15,$D$5:$D$539,D15,$F$5:$F$539,F15)>1,"YES","No") -> No | N15: =IFERROR(INDEX(Customer_Master!$B$5:$B$64,MATCH(B15,Customer_Master!$A$5:$A$64,0)),"UNMATCHED") -> Joy Lawal | O15: =IFERROR(INDEX(Customer_Master!$C$5:$C$64,MATCH(B15,Customer_Master!$A$5:$A$64,0)),"UNMATCHED") -> Lost / Low-Value | P15: =IFERROR(INDEX(Customer_Master!$D$5:$D$64,MATCH(B15,Customer_Master!$A$5:$A$64,0)),"UNMATCHED") -> Abuja | Q15: =IF(N15="UNMATCHED","Unmatched","Matched") -> Matched | R15: =IF(OR(E15="No",G15="No",I15="No",L15="YES",Q15="Unmatched"),"NEEDS REVIEW","OK") -> OK
A16: =Orders_Raw!A16 -> ORD00503 | B16: =TRIM(UPPER(Orders_Raw!B16)) -> CUST0044 | C16: =PROPER(TRIM(Orders_Raw!C16)) -> Emeka Yakubu | D16: =IFERROR(DATEVALUE(Orders_Raw!D16),"") -> 46090 | E16: =IF(D16="","No","Yes") -> Yes | F16: =IFERROR(VALUE(SUBSTITUTE(SUBSTITUTE(SUBSTITUTE(Orders_Raw!G16,"$",""),"NGN",""),",","")),"") -> 1333.15 | G16: =IF(F16="","No","Yes") -> Yes | H16: =Orders_Raw!F16 -> 1 | I16: =IF(H16="","No",IF(H16<=0,"No","Yes")) -> Yes | J16: =Orders_Raw!E16 -> Monitor | K16: =Orders_Raw!H16 -> 2026-03-09 18:20 | L16: =IF(COUNTIF(Orders_Raw!$A$5:$A$539,A16)>1,"YES","No") -> No | M16: =IF(COUNTIFS($B$5:$B$539,B16,$D$5:$D$539,D16,$F$5:$F$539,F16)>1,"YES","No") -> No | N16: =IFERROR(INDEX(Customer_Master!$B$5:$B$64,MATCH(B16,Customer_Master!$A$5:$A$64,0)),"UNMATCHED") -> Emeka Yakubu | O16: =IFERROR(INDEX(Customer_Master!$C$5:$C$64,MATCH(B16,Customer_Master!$A$5:$A$64,0)),"UNMATCHED") -> Champions | P16: =IFERROR(INDEX(Customer_Master!$D$5:$D$64,MATCH(B16,Customer_Master!$A$5:$A$64,0)),"UNMATCHED") -> Port Harcourt | Q16: =IF(N16="UNMATCHED","Unmatched","Matched") -> Matched | R16: =IF(OR(E16="No",G16="No",I16="No",L16="YES",Q16="Unmatched"),"NEEDS REVIEW","OK") -> OK
... A539: =Orders_Raw!A539 -> ORD00250 | B539: =TRIM(UPPER(Orders_Raw!B539)) -> CUST0003 | C539: =PROPER(TRIM(Orders_Raw!C539)) -> Chidi Adamu | D539: =IFERROR(DATEVALUE(Orders_Raw!D539),"") -> 46128 | E539: =IF(D539="","No","Yes") -> Yes | F539: =IFERROR(VALUE(SUBSTITUTE(SUBSTITUTE(SUBSTITUTE(Orders_Raw!G539,"$",""),"NGN",""),",","")),"") -> 1154.27 | G539: =IF(F539="","No","Yes") -> Yes | H539: =Orders_Raw!F539 -> 3 | I539: =IF(H539="","No",IF(H539<=0,"No","Yes")) -> Yes | J539: =Orders_Raw!E539 -> Monitor | K539: =Orders_Raw!H539 -> 2026-04-16 09:37 | L539: =IF(COUNTIF(Orders_Raw!$A$5:$A$539,A539)>1,"YES","No") -> No | M539: =IF(COUNTIFS($B$5:$B$539,B539,$D$5:$D$539,D539,$F$5:$F$539,F539)>1,"YES","No") -> No | N539: =IFERROR(INDEX(Customer_Master!$B$5:$B$64,MATCH(B539,Customer_Master!$A$5:$A$64,0)),"UNMATCHED") -> Chidi Adamu | O539: =IFERROR(INDEX(Customer_Master!$C$5:$C$64,MATCH(B539,Customer_Master!$A$5:$A$64,0)),"UNMATCHED") -> Champions | P539: =IFERROR(INDEX(Customer_Master!$D$5:$D$64,MATCH(B539,Customer_Master!$A$5:$A$64,0)),"UNMATCHED") -> Enugu | Q539: =IF(N539="UNMATCHED","Unmatched","Matched") -> Matched | R539: =IF(OR(E539="No",G539="No",I539="No",L539="YES",Q539="Unmatched"),"NEEDS REVIEW","OK") -> OK

Sheet Dashboard
A1: Data Reconciliation & Quality Dashboard
A2: Live summary of order volume, data quality, and revenue reconciliation
A4: Total Orders | C4: Needs Review | E4: Clean (OK) | G4: Error Rate (%)
A5: =COUNTA(Cleaned_Orders!A5:A539) -> 535 | C5: =COUNTIF(Cleaned_Orders!R5:R539,"NEEDS REVIEW") -> 162 | E5: =COUNTIF(Cleaned_Orders!R5:R539,"OK") -> 373 | G5: =ROUND(COUNTIF(Cleaned_Orders!R5:R539,"NEEDS REVIEW")/COUNTA(Cleaned_Orders!A5:A539)*100,1) -> 30.3
A7: Duplicate Orders | C7: Unmatched Customers | E7: Invalid Dates | G7: Invalid Amounts
A8: =COUNTIF(Cleaned_Orders!L5:L539,"YES") -> 30 | C8: =COUNTIF(Cleaned_Orders!Q5:Q539,"Unmatched") -> 20 | E8: =COUNTIF(Cleaned_Orders!E5:E539,"No") -> 123 | G8: =COUNTIF(Cleaned_Orders!G5:G539,"No") -> 0
A12: Revenue by Region (matched & valid orders only)
A13: Region | B13: Total Revenue | C13: Order Count
A14: Abuja | B14: =ROUND(SUMIFS(Cleaned_Orders!$F$5:$F$539,Cleaned_Orders!$P$5:$P$539,A14,Cleaned_Orders!$R$5:$R$539,"OK"),2) -> 85151.66 | C14: =COUNTIFS(Cleaned_Orders!$P$5:$P$539,A14,Cleaned_Orders!$R$5:$R$539,"OK") -> 69
A15: Enugu | B15: =ROUND(SUMIFS(Cleaned_Orders!$F$5:$F$539,Cleaned_Orders!$P$5:$P$539,A15,Cleaned_Orders!$R$5:$R$539,"OK"),2) -> 69619.22 | C15: =COUNTIFS(Cleaned_Orders!$P$5:$P$539,A15,Cleaned_Orders!$R$5:$R$539,"OK") -> 51
A16: Ibadan | B16: =ROUND(SUMIFS(Cleaned_Orders!$F$5:$F$539,Cleaned_Orders!$P$5:$P$539,A16,Cleaned_Orders!$R$5:$R$539,"OK"),2) -> 45806.48 | C16: =COUNTIFS(Cleaned_Orders!$P$5:$P$539,A16,Cleaned_Orders!$R$5:$R$539,"OK") -> 35
A17: Jos | B17: =ROUND(SUMIFS(Cleaned_Orders!$F$5:$F$539,Cleaned_Orders!$P$5:$P$539,A17,Cleaned_Orders!$R$5:$R$539,"OK"),2) -> 21926.05 | C17: =COUNTIFS(Cleaned_Orders!$P$5:$P$539,A17,Cleaned_Orders!$R$5:$R$539,"OK") -> 15
A18: Kaduna | B18: =ROUND(SUMIFS(Cleaned_Orders!$F$5:$F$539,Cleaned_Orders!$P$5:$P$539,A18,Cleaned_Orders!$R$5:$R$539,"OK"),2) -> 69928.7 | C18: =COUNTIFS(Cleaned_Orders!$P$5:$P$539,A18,Cleaned_Orders!$R$5:$R$539,"OK") -> 55
A19: Kano | B19: =ROUND(SUMIFS(Cleaned_Orders!$F$5:$F$539,Cleaned_Orders!$P$5:$P$539,A19,Cleaned_Orders!$R$5:$R$539,"OK"),2) -> 83404.1 | C19: =COUNTIFS(Cleaned_Orders!$P$5:$P$539,A19,Cleaned_Orders!$R$5:$R$539,"OK") -> 67
A20: Lagos | B20: =ROUND(SUMIFS(Cleaned_Orders!$F$5:$F$539,Cleaned_Orders!$P$5:$P$539,A20,Cleaned_Orders!$R$5:$R$539,"OK"),2) -> 61557.32 | C20: =COUNTIFS(Cleaned_Orders!$P$5:$P$539,A20,Cleaned_Orders!$R$5:$R$539,"OK") -> 50
A21: Port Harcourt | B21: =ROUND(SUMIFS(Cleaned_Orders!$F$5:$F$539,Cleaned_Orders!$P$5:$P$539,A21,Cleaned_Orders!$R$5:$R$539,"OK"),2) -> 43359.1 | C21: =COUNTIFS(Cleaned_Orders!$P$5:$P$539,A21,Cleaned_Orders!$R$5:$R$539,"OK") -> 31

Sheet Entry_Log
A1: Entry Audit Log
A2: Tracks when order records were entered into the system, by month
A4: Month | B4: Orders Entered
A5: 2026-01 | B5: =COUNTIF(Cleaned_Orders!$K$5:$K$539,"2026-01*") -> 83
A6: 2026-02 | B6: =COUNTIF(Cleaned_Orders!$K$5:$K$539,"2026-02*") -> 55
A7: 2026-03 | B7: =COUNTIF(Cleaned_Orders!$K$5:$K$539,"2026-03*") -> 90
A8: 2026-04 | B8: =COUNTIF(Cleaned_Orders!$K$5:$K$539,"2026-04*") -> 71
A9: 2026-05 | B9: =COUNTIF(Cleaned_Orders!$K$5:$K$539,"2026-05*") -> 92
A10: 2026-06 | B10: =COUNTIF(Cleaned_Orders!$K$5:$K$539,"2026-06*") -> 83
A11: 2026-07 | B11: =COUNTIF(Cleaned_Orders!$K$5:$K$539,"2026-07*") -> 61

Sheet README
A1: Project: Advanced Multi-Source Data Reconciliation & Reporting System
A3: Overview:
A4: This project simulates reconciling 535 real-world messy order entries against a
A5: clean 60-customer master list — a common data entry task when records are entered by
A6: different people, systems, or channels and need to be checked, matched, and cleaned
A7: before reporting.
A9: What it includes:
A10: 1. Orders_Raw — raw, unedited order data containing realistic entry errors: inconsistent
A11: capitalization/spacing, three different date formats, mixed currency formatting
A12: ($, NGN, plain), typo'd customer IDs, missing/negative quantities, and duplicate
A13: re-entries.
A14: 2. Customer_Master — the clean authoritative reference list used for reconciliation.
... A32: row-by-row checking.
